[2019-04-12 12:48:53,597] [_internal.py:122	] [INFO]   * Running on http://127.0.0.1:5000/ (Press CTRL+C to quit) 
[2019-04-12 13:22:22,396] [_internal.py:122	] [INFO]   * Running on http://127.0.0.1:5000/ (Press CTRL+C to quit) 
[2019-04-12 13:22:53,708] [_internal.py:122	] [INFO]  127.0.0.1 - - [12/Apr/2019 13:22:53] "POST /api/v1/login HTTP/1.1" 200 - 
[2019-04-12 13:22:58,533] [app.py:1761	] [ERROR]  Exception on /api/v1/login [POST] 
Traceback (most recent call last):
  File "/Library/Frameworks/Python.framework/Versions/3.6/lib/python3.6/site-packages/mongoengine/queryset/base.py", line 268, in get
    result = six.next(queryset)
  File "/Library/Frameworks/Python.framework/Versions/3.6/lib/python3.6/site-packages/mongoengine/queryset/base.py", line 1495, in __next__
    raw_doc = six.next(self._cursor)
  File "/Library/Frameworks/Python.framework/Versions/3.6/lib/python3.6/site-packages/pymongo/cursor.py", line 1197, in next
    raise StopIteration
StopIteration

During handling of the above exception, another exception occurred:

Traceback (most recent call last):
  File "/Library/Frameworks/Python.framework/Versions/3.6/lib/python3.6/site-packages/flask/app.py", line 2292, in wsgi_app
    response = self.full_dispatch_request()
  File "/Library/Frameworks/Python.framework/Versions/3.6/lib/python3.6/site-packages/flask/app.py", line 1815, in full_dispatch_request
    rv = self.handle_user_exception(e)
  File "/Library/Frameworks/Python.framework/Versions/3.6/lib/python3.6/site-packages/flask/app.py", line 1718, in handle_user_exception
    reraise(exc_type, exc_value, tb)
  File "/Library/Frameworks/Python.framework/Versions/3.6/lib/python3.6/site-packages/flask/_compat.py", line 35, in reraise
    raise value
  File "/Library/Frameworks/Python.framework/Versions/3.6/lib/python3.6/site-packages/flask/app.py", line 1813, in full_dispatch_request
    rv = self.dispatch_request()
  File "/Library/Frameworks/Python.framework/Versions/3.6/lib/python3.6/site-packages/flask/app.py", line 1799, in dispatch_request
    return self.view_functions[rule.endpoint](**req.view_args)
  File "/Library/Frameworks/Python.framework/Versions/3.6/lib/python3.6/site-packages/flask/views.py", line 88, in view
    return self.dispatch_request(*args, **kwargs)
  File "/Library/Frameworks/Python.framework/Versions/3.6/lib/python3.6/site-packages/flask/views.py", line 158, in dispatch_request
    return meth(*args, **kwargs)
  File "/Users/dream-mac/PycharmProjects/flask_check_list/views/view.py", line 39, in post
    user_object = User.objects.get(username=username, pwd=password)
  File "/Library/Frameworks/Python.framework/Versions/3.6/lib/python3.6/site-packages/mongoengine/queryset/base.py", line 272, in get
    raise queryset._document.DoesNotExist(msg)
flask_check_list.views.models.DoesNotExist: User matching query does not exist.
[2019-04-12 13:22:58,544] [_internal.py:122	] [INFO]  127.0.0.1 - - [12/Apr/2019 13:22:58] "POST /api/v1/login HTTP/1.1" 500 - 
[2019-04-12 13:24:41,808] [_internal.py:122	] [INFO]   * Running on http://127.0.0.1:5000/ (Press CTRL+C to quit) 
[2019-04-12 13:24:43,853] [app.py:1761	] [ERROR]  Exception on /api/v1/login [POST] 
Traceback (most recent call last):
  File "/Library/Frameworks/Python.framework/Versions/3.6/lib/python3.6/site-packages/mongoengine/queryset/base.py", line 268, in get
    result = six.next(queryset)
  File "/Library/Frameworks/Python.framework/Versions/3.6/lib/python3.6/site-packages/mongoengine/queryset/base.py", line 1495, in __next__
    raw_doc = six.next(self._cursor)
  File "/Library/Frameworks/Python.framework/Versions/3.6/lib/python3.6/site-packages/pymongo/cursor.py", line 1197, in next
    raise StopIteration
StopIteration

During handling of the above exception, another exception occurred:

Traceback (most recent call last):
  File "/Users/dream-mac/PycharmProjects/flask_check_list/views/view.py", line 40, in post
    user_object = User.objects.get(username=username, pwd=password)
  File "/Library/Frameworks/Python.framework/Versions/3.6/lib/python3.6/site-packages/mongoengine/queryset/base.py", line 272, in get
    raise queryset._document.DoesNotExist(msg)
flask_check_list.views.models.DoesNotExist: User matching query does not exist.

During handling of the above exception, another exception occurred:

Traceback (most recent call last):
  File "/Library/Frameworks/Python.framework/Versions/3.6/lib/python3.6/site-packages/flask/app.py", line 2292, in wsgi_app
    response = self.full_dispatch_request()
  File "/Library/Frameworks/Python.framework/Versions/3.6/lib/python3.6/site-packages/flask/app.py", line 1815, in full_dispatch_request
    rv = self.handle_user_exception(e)
  File "/Library/Frameworks/Python.framework/Versions/3.6/lib/python3.6/site-packages/flask/app.py", line 1718, in handle_user_exception
    reraise(exc_type, exc_value, tb)
  File "/Library/Frameworks/Python.framework/Versions/3.6/lib/python3.6/site-packages/flask/_compat.py", line 35, in reraise
    raise value
  File "/Library/Frameworks/Python.framework/Versions/3.6/lib/python3.6/site-packages/flask/app.py", line 1813, in full_dispatch_request
    rv = self.dispatch_request()
  File "/Library/Frameworks/Python.framework/Versions/3.6/lib/python3.6/site-packages/flask/app.py", line 1799, in dispatch_request
    return self.view_functions[rule.endpoint](**req.view_args)
  File "/Library/Frameworks/Python.framework/Versions/3.6/lib/python3.6/site-packages/flask/views.py", line 88, in view
    return self.dispatch_request(*args, **kwargs)
  File "/Library/Frameworks/Python.framework/Versions/3.6/lib/python3.6/site-packages/flask/views.py", line 158, in dispatch_request
    return meth(*args, **kwargs)
  File "/Users/dream-mac/PycharmProjects/flask_check_list/views/view.py", line 42, in post
    raise ValueError("queryset._document.DoesNotExist(msg)")
ValueError: queryset._document.DoesNotExist(msg)
[2019-04-12 13:24:43,858] [_internal.py:122	] [INFO]  127.0.0.1 - - [12/Apr/2019 13:24:43] "POST /api/v1/login HTTP/1.1" 500 - 
[2019-04-12 13:26:08,478] [_internal.py:122	] [INFO]   * Running on http://127.0.0.1:5000/ (Press CTRL+C to quit) 
[2019-04-12 13:26:12,104] [_internal.py:122	] [INFO]  127.0.0.1 - - [12/Apr/2019 13:26:12] "POST /api/v1/login HTTP/1.1" 200 - 
[2019-04-12 13:26:39,631] [_internal.py:122	] [INFO]   * Running on http://127.0.0.1:5000/ (Press CTRL+C to quit) 
[2019-04-12 13:26:41,857] [_internal.py:122	] [INFO]  127.0.0.1 - - [12/Apr/2019 13:26:41] "POST /api/v1/login HTTP/1.1" 200 - 
[2019-04-12 13:28:47,375] [_internal.py:122	] [INFO]   * Running on http://127.0.0.1:5000/ (Press CTRL+C to quit) 
[2019-04-12 13:28:52,595] [view.py:69	] [ERROR]  {'code': 500, 'data': 'sorry, login failed, username or password was wrong, please try again', 'error': None} 
[2019-04-12 13:28:52,597] [_internal.py:122	] [INFO]  127.0.0.1 - - [12/Apr/2019 13:28:52] "POST /api/v1/login HTTP/1.1" 200 - 
[2019-04-12 13:43:14,630] [_internal.py:122	] [INFO]   * Running on http://127.0.0.1:5000/ (Press CTRL+C to quit) 
